{
  "xsize": 16,
  "zsize": 16,
  "slices": [
    [
      "################",
      "################",
      "################",
      "################",
      "################",
      "################",
      "################",
      "################",
      "################",
      "#######l########",
      "################",
      "################",
      "################",
      "################",
      "################",
      "################"
    ],
    [
      "#aa@aaaaaaaa@aa#",
      "aWWWWWWWWWWWWWWa",
      "aWWWWWWWWWWWWWWa",
      "@WWWWWWWWWWWWWW@",
      "aWWWWWWWWWWWWWWa",
      "aaaaaaaaaaaaaaaa",
      "a              a",
      "aC             a",
      "aL             a",
      "aF     l       a",
      "aF    ###::::::a",
      "aC     :   F   a",
      "@      :   T   @",
      "a      :   F   a",
      "a     C:       a",
      "#aa@aaaaaaaa@aa#"
    ],
    [
      "#aa@aaaaaaaa@aa#",
      "aWWWWWWWWWWWWWWa",
      "aWWWWWWWWWWWWWWa",
      "@WWWWWWWWWWWWWW@",
      "aWWWWWWWWWWWWWWa",
      "aaaaaaaaaaaaaaaa",
      "a              a",
      "a              a",
      "aL             a",
      "a      l       a",
      "a     ###::::::a",
      "a      :       a",
      "@      :       @",
      "a      :       a",
      "a      :       a",
      "#aa@aaaaaaaa@aa#"
    ],
    [
      "#aa@aaaaaaaa@aa#",
      "aWWWWWWWWWWWWWWa",
      "aWWWWWWWWWWWWWWa",
      "@WWWWWWWWWWWWWW@",
      "aWWWWWWWWWWWWWWa",
      "aaaaaaaaaaaaaaaa",
      "a              a",
      "a              a",
      "aL             a",
      "a      l       a",
      "a     ###::::::a",
      "a      :       a",
      "@      :       @",
      "a      :       a",
      "a      :       a",
      "#aa@aaaaaaaa@aa#"
    ],
    [
      "################",
      "################",
      "################",
      "################",
      "################",
      "################",
      "################",
      "################",
      "################",
      "#######l########",
      "################",
      "################",
      "##1#1###########",
      "################",
      "################",
      "################"
    ],
    [
      "################",
      "################",
      "################",
      "################",
      "################",
      "################",
      "################",
      "################",
      "################",
      "#######l########",
      "################",
      "################",
      "################",
      "################",
      "################",
      "################"
    ]
  ]
}