{
  "xsize": 16,
  "zsize": 16,
  "slices": [
    [
      "################",
      "################",
      "################",
      "################",
      "################",
      "################",
      "################",
      "################",
      "################",
      "#######l########",
      "####X1X#X1X#####",
      "#####X###X######",
      "################",
      "################",
      "################",
      "################"
    ],
    [
      "#aa@aaaaaaaa@aa#",
      "a      #       a",
      "a  C   #F      a",
      "@              @",
      "a      #       a",
      "a     L#       a",
      "a    #####     a",
      "a    #   #     a",
      "a    #   #F    a",
      "a      l #     a",
      "a########X     a",
      "a   C   :      a",
      "@       :      @",
      "a              a",
      "a              a",
      "#aa@aaaaaaaa@aa#"
    ],
    [
      "#aa@aaaaaaaa@aa#",
      "a      #       a",
      "a      #       a",
      "@              @",
      "a      #       a",
      "a     L#       a",
      "a    #####     a",
      "a    #   #     a",
      "a    #   #T    a",
      "a      l #     a",
      "a#########     a",
      "a    T  :      a",
      "@       :      @",
      "a              a",
      "a              a",
      "#aa@aaaaaaaa@aa#"
    ],
    [
      "#aa@aaaaaaaa@aa#",
      "a      #       a",
      "a      #       a",
      "@      #       @",
      "a      #       a",
      "a     L#       a",
      "a    #####     a",
      "a    #   #     a",
      "a    #   #     a",
      "a    # l #     a",
      "a#########     a",
      "a       :      a",
      "@       :      @",
      "a              a",
      "a              a",
      "#aa@aaaaaaaa@aa#"
    ],
    [
      "################",
      "################",
      "################",
      "################",
      "################",
      "################",
      "################",
      "################",
      "################",
      "#######l########",
      "################",
      "################",
      "################",
      "################",
      "################",
      "################"
    ],
    [
      "################",
      "################",
      "################",
      "################",
      "################",
      "################",
      "################",
      "################",
      "################",
      "#######l########",
      "################",
      "################",
      "################",
      "################",
      "################",
      "################"
    ]
  ]
}